<mujoco model="base">
  <compiler angle="radian" meshdir="meshes/" autolimits="true"/>
  <option impratio="20" density="1.2" viscosity="2e-05" cone="elliptic"/>
  <size njmax="5000" nconmax="5000"/>
  <visual>
    <map znear="0.001"/>
  </visual>
  <default/>
  <asset>
    <texture type="skybox" builtin="gradient" rgb1="0.9 0.9 1" rgb2="0.2 0.3 0.4" width="256" height="1536"/>
    <texture type="2d" name="texplane" file="/Users/yilongsong/Documents/Brown/robotics/MimicGen/installation_new/robosuite/robosuite/models/assets/arenas/../textures/light-gray-floor-tile.png"/>
    <texture type="cube" name="tex-ceramic" file="/Users/yilongsong/Documents/Brown/robotics/MimicGen/installation_new/robosuite/robosuite/models/assets/arenas/../textures/ceramic.png"/>
    <texture type="cube" name="tex-steel-brushed" file="/Users/yilongsong/Documents/Brown/robotics/MimicGen/installation_new/robosuite/robosuite/models/assets/arenas/../textures/steel-brushed.png"/>
    <texture type="2d" name="tex-light-gray-plaster" file="/Users/yilongsong/Documents/Brown/robotics/MimicGen/installation_new/robosuite/robosuite/models/assets/arenas/../textures/light-gray-plaster.png"/>
    <texture type="cube" name="textable" builtin="flat" rgb1="0.5 0.5 0.5" width="512" height="3072"/>
    <texture type="cube" name="Door_light-wood" file="/Users/yilongsong/Documents/Brown/robotics/MimicGen/installation_new/robosuite/robosuite/models/assets/objects/../textures/light-wood.png"/>
    <texture type="cube" name="Door_dark-wood" file="/Users/yilongsong/Documents/Brown/robotics/MimicGen/installation_new/robosuite/robosuite/models/assets/objects/../textures/dark-wood.png"/>
    <texture type="cube" name="Door_metal" file="/Users/yilongsong/Documents/Brown/robotics/MimicGen/installation_new/robosuite/robosuite/models/assets/objects/../textures/brass-ambra.png"/>
    <material name="floorplane" texture="texplane" texuniform="true" texrepeat="2 2" specular="0" shininess="0" reflectance="0.01"/>
    <material name="table_ceramic" texture="tex-ceramic" specular="0.2" shininess="0"/>
    <material name="table_legs_metal" texture="tex-steel-brushed" shininess="0.8" reflectance="0.8"/>
    <material name="walls_mat" texture="tex-light-gray-plaster" texuniform="true" texrepeat="3 3" specular="0.1" shininess="0.1"/>
    <material name="table_mat" texture="textable"/>
    <material name="robot0_Face636_001" shininess="0.45" rgba="0.901961 0.921569 0.929412 1"/>
    <material name="robot0_Part__Feature017_001" shininess="0.45"/>
    <material name="robot0_Part__Feature018_001" shininess="0.45"/>
    <material name="robot0_Part__Feature019_001" shininess="0.45"/>
    <material name="robot0_Part__Feature022_001" shininess="0.45" rgba="0.901961 0.921569 0.929412 1"/>
    <material name="robot0_Part__Feature023_001" shininess="0.45" rgba="0.25098 0.25098 0.25098 1"/>
    <material name="robot0_Shell001_001" shininess="0.45" rgba="0.25098 0.25098 0.25098 1"/>
    <material name="robot0_Shell002_001" shininess="0.45" rgba="0.901961 0.921569 0.929412 1"/>
    <material name="robot0_Shell003_001" shininess="0.45" rgba="0.901961 0.921569 0.929412 1"/>
    <material name="robot0_Shell009_001" shininess="0.45" rgba="0.25098 0.25098 0.25098 1"/>
    <material name="robot0_Shell010_001" shininess="0.45" rgba="0.901961 0.921569 0.929412 1"/>
    <material name="robot0_Shell_001" shininess="0.45" rgba="0.25098 0.25098 0.25098 1"/>
    <material name="robot0_Part__Feature_001" shininess="0.45"/>
    <material name="robot0_Part__Feature024" shininess="0.45"/>
    <material name="robot0_Part__Feature001_010_001_002" shininess="0.45"/>
    <material name="robot0_Part__Feature002_007_001_002" shininess="0.45"/>
    <material name="robot0_Part__Feature003_004_001_002" shininess="0.45"/>
    <material name="robot0_Part__Feature_001_001_001_002" shininess="0.45" rgba="0.25098 0.25098 0.25098 1"/>
    <material name="robot0_Part__Feature001_001_003_001" shininess="0.45"/>
    <material name="robot0_Part__Feature002_001_003_001" shininess="0.45" rgba="0.25098 0.25098 0.25098 1"/>
    <material name="robot0_Part__Feature003_001_003_001" shininess="0.45"/>
    <material name="robot0_Part__Feature_002_003_001" shininess="0.45"/>
    <material name="robot0_Part__Feature_002_004_003" shininess="0.45"/>
    <material name="robot0_Shell001_001_001_003" shininess="0.45" rgba="0.25 0.25 0.25 1"/>
    <material name="robot0_Shell_001_001_003" shininess="0.45"/>
    <material name="robot0_Face064_002_001_002_001" shininess="0.45" rgba="1 0 0 1"/>
    <material name="robot0_Face065_002_001_002_001" shininess="0.45" rgba="0 1 0 1"/>
    <material name="robot0_Face374_002_001_002_001" shininess="0.45"/>
    <material name="robot0_Face539_002_001_002_001" shininess="0.45" rgba="0.25098 0.25098 0.25098 1"/>
    <material name="robot0_Part__Feature001_009_001_002_001" shininess="0.45" rgba="0.25098 0.25098 0.25098 1"/>
    <material name="robot0_Part__Feature002_006_001_002_001" shininess="0.45" rgba="0.25098 0.25098 0.25098 1"/>
    <material name="robot0_Shell002_002_001_002_001" shininess="0.45"/>
    <material name="robot0_Shell003_002_001_002_001" shininess="0.45"/>
    <material name="robot0_Shell004_001_001_002_001" shininess="0.45"/>
    <material name="robot0_Shell005_001_001_002_001" shininess="0.45"/>
    <material name="robot0_Shell006_003_002_001" shininess="0.45" rgba="0.901961 0.921569 0.929412 1"/>
    <material name="robot0_Shell007_002_002_001" shininess="0.45" rgba="0.25 0.25 0.25 1"/>
    <material name="robot0_Shell011_002_002_001" shininess="0.45"/>
    <material name="robot0_Shell012_002_002_001" shininess="0.45"/>
    <material name="robot0_Shell_003_001_002_001" shininess="0.45" rgba="0.25098 0.25098 0.25098 1"/>
    <material name="robot0_Union001_001_001_002_001" shininess="0.45" rgba="0.039216 0.541176 0.780392 1"/>
    <material name="robot0_Union_001_001_002_001" shininess="0.45" rgba="0.039216 0.541176 0.780392 1"/>
    <material name="robot0_Part__Mirroring001_004_002" shininess="0.45" rgba="0.25098 0.25098 0.25098 1"/>
    <material name="robot0_Part__Mirroring002_004_001" shininess="0.45" rgba="0.25098 0.25098 0.25098 1"/>
    <material name="robot0_Part__Mirroring003_004_001" shininess="0.45" rgba="0.25098 0.25098 0.25098 1"/>
    <material name="robot0_Part__Mirroring004_004_002" shininess="0.45"/>
    <material name="robot0_Part__Mirroring005_004_001" shininess="0.45" rgba="0.25098 0.25098 0.25098 1"/>
    <material name="robot0_Part__Mirroring006_004_001" shininess="0.45" rgba="0.25098 0.25098 0.25098 1"/>
    <material name="robot0_Part__Mirroring007_004_001" shininess="0.45" rgba="0.25098 0.25098 0.25098 1"/>
    <material name="robot0_Part__Mirroring_004_001" shininess="0.45" rgba="0.898039 0.917647 0.929412 1"/>
    <material name="Door_MatMetal" texture="Door_metal" specular="1" shininess="0.3" rgba="0.9 0.9 0.9 1"/>
    <material name="Door_MatDarkWood" texture="Door_dark-wood" texrepeat="3 3" specular="0.4" shininess="0.1"/>
    <material name="Door_MatLightWood" texture="Door_light-wood" texrepeat="3 3" specular="0.4" shininess="0.1"/>
    <mesh name="robot0_link0" file="/Users/yilongsong/Documents/Brown/robotics/MimicGen/installation_new/robosuite/robosuite/models/assets/robots/panda/meshes/link0.stl"/>
    <mesh name="robot0_link1" file="/Users/yilongsong/Documents/Brown/robotics/MimicGen/installation_new/robosuite/robosuite/models/assets/robots/panda/meshes/link1.stl"/>
    <mesh name="robot0_link2" file="/Users/yilongsong/Documents/Brown/robotics/MimicGen/installation_new/robosuite/robosuite/models/assets/robots/panda/meshes/link2.stl"/>
    <mesh name="robot0_link3" file="/Users/yilongsong/Documents/Brown/robotics/MimicGen/installation_new/robosuite/robosuite/models/assets/robots/panda/meshes/link3.stl"/>
    <mesh name="robot0_link4" file="/Users/yilongsong/Documents/Brown/robotics/MimicGen/installation_new/robosuite/robosuite/models/assets/robots/panda/meshes/link4.stl"/>
    <mesh name="robot0_link5" file="/Users/yilongsong/Documents/Brown/robotics/MimicGen/installation_new/robosuite/robosuite/models/assets/robots/panda/meshes/link5.stl"/>
    <mesh name="robot0_link6" file="/Users/yilongsong/Documents/Brown/robotics/MimicGen/installation_new/robosuite/robosuite/models/assets/robots/panda/meshes/link6.stl"/>
    <mesh name="robot0_link7" file="/Users/yilongsong/Documents/Brown/robotics/MimicGen/installation_new/robosuite/robosuite/models/assets/robots/panda/meshes/link7.stl"/>
    <mesh name="robot0_link0_vis_0" file="/Users/yilongsong/Documents/Brown/robotics/MimicGen/installation_new/robosuite/robosuite/models/assets/robots/panda/obj_meshes/link0_vis/link0_vis_0.obj"/>
    <mesh name="robot0_link0_vis_1" file="/Users/yilongsong/Documents/Brown/robotics/MimicGen/installation_new/robosuite/robosuite/models/assets/robots/panda/obj_meshes/link0_vis/link0_vis_1.obj"/>
    <mesh name="robot0_link0_vis_2" file="/Users/yilongsong/Documents/Brown/robotics/MimicGen/installation_new/robosuite/robosuite/models/assets/robots/panda/obj_meshes/link0_vis/link0_vis_2.obj"/>
    <mesh name="robot0_link0_vis_3" file="/Users/yilongsong/Documents/Brown/robotics/MimicGen/installation_new/robosuite/robosuite/models/assets/robots/panda/obj_meshes/link0_vis/link0_vis_3.obj"/>
    <mesh name="robot0_link0_vis_4" file="/Users/yilongsong/Documents/Brown/robotics/MimicGen/installation_new/robosuite/robosuite/models/assets/robots/panda/obj_meshes/link0_vis/link0_vis_4.obj"/>
    <mesh name="robot0_link0_vis_5" file="/Users/yilongsong/Documents/Brown/robotics/MimicGen/installation_new/robosuite/robosuite/models/assets/robots/panda/obj_meshes/link0_vis/link0_vis_5.obj"/>
    <mesh name="robot0_link0_vis_6" file="/Users/yilongsong/Documents/Brown/robotics/MimicGen/installation_new/robosuite/robosuite/models/assets/robots/panda/obj_meshes/link0_vis/link0_vis_6.obj"/>
    <mesh name="robot0_link0_vis_7" file="/Users/yilongsong/Documents/Brown/robotics/MimicGen/installation_new/robosuite/robosuite/models/assets/robots/panda/obj_meshes/link0_vis/link0_vis_7.obj"/>
    <mesh name="robot0_link0_vis_8" file="/Users/yilongsong/Documents/Brown/robotics/MimicGen/installation_new/robosuite/robosuite/models/assets/robots/panda/obj_meshes/link0_vis/link0_vis_8.obj"/>
    <mesh name="robot0_link0_vis_9" file="/Users/yilongsong/Documents/Brown/robotics/MimicGen/installation_new/robosuite/robosuite/models/assets/robots/panda/obj_meshes/link0_vis/link0_vis_9.obj"/>
    <mesh name="robot0_link0_vis_10" file="/Users/yilongsong/Documents/Brown/robotics/MimicGen/installation_new/robosuite/robosuite/models/assets/robots/panda/obj_meshes/link0_vis/link0_vis_10.obj"/>
    <mesh name="robot0_link0_vis_11" file="/Users/yilongsong/Documents/Brown/robotics/MimicGen/installation_new/robosuite/robosuite/models/assets/robots/panda/obj_meshes/link0_vis/link0_vis_11.obj"/>
    <mesh name="robot0_link1_vis" file="/Users/yilongsong/Documents/Brown/robotics/MimicGen/installation_new/robosuite/robosuite/models/assets/robots/panda/obj_meshes/link1_vis/link1_vis.obj"/>
    <mesh name="robot0_link2_vis" file="/Users/yilongsong/Documents/Brown/robotics/MimicGen/installation_new/robosuite/robosuite/models/assets/robots/panda/obj_meshes/link2_vis/link2_vis.obj"/>
    <mesh name="robot0_link3_vis_0" file="/Users/yilongsong/Documents/Brown/robotics/MimicGen/installation_new/robosuite/robosuite/models/assets/robots/panda/obj_meshes/link3_vis/link3_vis_0.obj"/>
    <mesh name="robot0_link3_vis_1" file="/Users/yilongsong/Documents/Brown/robotics/MimicGen/installation_new/robosuite/robosuite/models/assets/robots/panda/obj_meshes/link3_vis/link3_vis_1.obj"/>
    <mesh name="robot0_link3_vis_2" file="/Users/yilongsong/Documents/Brown/robotics/MimicGen/installation_new/robosuite/robosuite/models/assets/robots/panda/obj_meshes/link3_vis/link3_vis_2.obj"/>
    <mesh name="robot0_link3_vis_3" file="/Users/yilongsong/Documents/Brown/robotics/MimicGen/installation_new/robosuite/robosuite/models/assets/robots/panda/obj_meshes/link3_vis/link3_vis_3.obj"/>
    <mesh name="robot0_link4_vis_0" file="/Users/yilongsong/Documents/Brown/robotics/MimicGen/installation_new/robosuite/robosuite/models/assets/robots/panda/obj_meshes/link4_vis/link4_vis_0.obj"/>
    <mesh name="robot0_link4_vis_1" file="/Users/yilongsong/Documents/Brown/robotics/MimicGen/installation_new/robosuite/robosuite/models/assets/robots/panda/obj_meshes/link4_vis/link4_vis_1.obj"/>
    <mesh name="robot0_link4_vis_2" file="/Users/yilongsong/Documents/Brown/robotics/MimicGen/installation_new/robosuite/robosuite/models/assets/robots/panda/obj_meshes/link4_vis/link4_vis_2.obj"/>
    <mesh name="robot0_link4_vis_3" file="/Users/yilongsong/Documents/Brown/robotics/MimicGen/installation_new/robosuite/robosuite/models/assets/robots/panda/obj_meshes/link4_vis/link4_vis_3.obj"/>
    <mesh name="robot0_link5_vis_0" file="/Users/yilongsong/Documents/Brown/robotics/MimicGen/installation_new/robosuite/robosuite/models/assets/robots/panda/obj_meshes/link5_vis/link5_vis_0.obj"/>
    <mesh name="robot0_link5_vis_1" file="/Users/yilongsong/Documents/Brown/robotics/MimicGen/installation_new/robosuite/robosuite/models/assets/robots/panda/obj_meshes/link5_vis/link5_vis_1.obj"/>
    <mesh name="robot0_link5_vis_2" file="/Users/yilongsong/Documents/Brown/robotics/MimicGen/installation_new/robosuite/robosuite/models/assets/robots/panda/obj_meshes/link5_vis/link5_vis_2.obj"/>
    <mesh name="robot0_link6_vis_0" file="/Users/yilongsong/Documents/Brown/robotics/MimicGen/installation_new/robosuite/robosuite/models/assets/robots/panda/obj_meshes/link6_vis/link6_vis_0.obj"/>
    <mesh name="robot0_link6_vis_1" file="/Users/yilongsong/Documents/Brown/robotics/MimicGen/installation_new/robosuite/robosuite/models/assets/robots/panda/obj_meshes/link6_vis/link6_vis_1.obj"/>
    <mesh name="robot0_link6_vis_2" file="/Users/yilongsong/Documents/Brown/robotics/MimicGen/installation_new/robosuite/robosuite/models/assets/robots/panda/obj_meshes/link6_vis/link6_vis_2.obj"/>
    <mesh name="robot0_link6_vis_3" file="/Users/yilongsong/Documents/Brown/robotics/MimicGen/installation_new/robosuite/robosuite/models/assets/robots/panda/obj_meshes/link6_vis/link6_vis_3.obj"/>
    <mesh name="robot0_link6_vis_4" file="/Users/yilongsong/Documents/Brown/robotics/MimicGen/installation_new/robosuite/robosuite/models/assets/robots/panda/obj_meshes/link6_vis/link6_vis_4.obj"/>
    <mesh name="robot0_link6_vis_5" file="/Users/yilongsong/Documents/Brown/robotics/MimicGen/installation_new/robosuite/robosuite/models/assets/robots/panda/obj_meshes/link6_vis/link6_vis_5.obj"/>
    <mesh name="robot0_link6_vis_6" file="/Users/yilongsong/Documents/Brown/robotics/MimicGen/installation_new/robosuite/robosuite/models/assets/robots/panda/obj_meshes/link6_vis/link6_vis_6.obj"/>
    <mesh name="robot0_link6_vis_7" file="/Users/yilongsong/Documents/Brown/robotics/MimicGen/installation_new/robosuite/robosuite/models/assets/robots/panda/obj_meshes/link6_vis/link6_vis_7.obj"/>
    <mesh name="robot0_link6_vis_8" file="/Users/yilongsong/Documents/Brown/robotics/MimicGen/installation_new/robosuite/robosuite/models/assets/robots/panda/obj_meshes/link6_vis/link6_vis_8.obj"/>
    <mesh name="robot0_link6_vis_9" file="/Users/yilongsong/Documents/Brown/robotics/MimicGen/installation_new/robosuite/robosuite/models/assets/robots/panda/obj_meshes/link6_vis/link6_vis_9.obj"/>
    <mesh name="robot0_link6_vis_10" file="/Users/yilongsong/Documents/Brown/robotics/MimicGen/installation_new/robosuite/robosuite/models/assets/robots/panda/obj_meshes/link6_vis/link6_vis_10.obj"/>
    <mesh name="robot0_link6_vis_11" file="/Users/yilongsong/Documents/Brown/robotics/MimicGen/installation_new/robosuite/robosuite/models/assets/robots/panda/obj_meshes/link6_vis/link6_vis_11.obj"/>
    <mesh name="robot0_link6_vis_12" file="/Users/yilongsong/Documents/Brown/robotics/MimicGen/installation_new/robosuite/robosuite/models/assets/robots/panda/obj_meshes/link6_vis/link6_vis_12.obj"/>
    <mesh name="robot0_link6_vis_13" file="/Users/yilongsong/Documents/Brown/robotics/MimicGen/installation_new/robosuite/robosuite/models/assets/robots/panda/obj_meshes/link6_vis/link6_vis_13.obj"/>
    <mesh name="robot0_link6_vis_14" file="/Users/yilongsong/Documents/Brown/robotics/MimicGen/installation_new/robosuite/robosuite/models/assets/robots/panda/obj_meshes/link6_vis/link6_vis_14.obj"/>
    <mesh name="robot0_link6_vis_15" file="/Users/yilongsong/Documents/Brown/robotics/MimicGen/installation_new/robosuite/robosuite/models/assets/robots/panda/obj_meshes/link6_vis/link6_vis_15.obj"/>
    <mesh name="robot0_link6_vis_16" file="/Users/yilongsong/Documents/Brown/robotics/MimicGen/installation_new/robosuite/robosuite/models/assets/robots/panda/obj_meshes/link6_vis/link6_vis_16.obj"/>
    <mesh name="robot0_link7_vis_0" file="/Users/yilongsong/Documents/Brown/robotics/MimicGen/installation_new/robosuite/robosuite/models/assets/robots/panda/obj_meshes/link7_vis/link7_vis_0.obj"/>
    <mesh name="robot0_link7_vis_1" file="/Users/yilongsong/Documents/Brown/robotics/MimicGen/installation_new/robosuite/robosuite/models/assets/robots/panda/obj_meshes/link7_vis/link7_vis_1.obj"/>
    <mesh name="robot0_link7_vis_2" file="/Users/yilongsong/Documents/Brown/robotics/MimicGen/installation_new/robosuite/robosuite/models/assets/robots/panda/obj_meshes/link7_vis/link7_vis_2.obj"/>
    <mesh name="robot0_link7_vis_3" file="/Users/yilongsong/Documents/Brown/robotics/MimicGen/installation_new/robosuite/robosuite/models/assets/robots/panda/obj_meshes/link7_vis/link7_vis_3.obj"/>
    <mesh name="robot0_link7_vis_4" file="/Users/yilongsong/Documents/Brown/robotics/MimicGen/installation_new/robosuite/robosuite/models/assets/robots/panda/obj_meshes/link7_vis/link7_vis_4.obj"/>
    <mesh name="robot0_link7_vis_5" file="/Users/yilongsong/Documents/Brown/robotics/MimicGen/installation_new/robosuite/robosuite/models/assets/robots/panda/obj_meshes/link7_vis/link7_vis_5.obj"/>
    <mesh name="robot0_link7_vis_6" file="/Users/yilongsong/Documents/Brown/robotics/MimicGen/installation_new/robosuite/robosuite/models/assets/robots/panda/obj_meshes/link7_vis/link7_vis_6.obj"/>
    <mesh name="robot0_link7_vis_7" file="/Users/yilongsong/Documents/Brown/robotics/MimicGen/installation_new/robosuite/robosuite/models/assets/robots/panda/obj_meshes/link7_vis/link7_vis_7.obj"/>
    <mesh name="mount0_pedestal" file="/Users/yilongsong/Documents/Brown/robotics/MimicGen/installation_new/robosuite/robosuite/models/assets/mounts/meshes/rethink_mount/pedestal.stl"/>
    <mesh name="gripper0_hand" file="/Users/yilongsong/Documents/Brown/robotics/MimicGen/installation_new/robosuite/robosuite/models/assets/grippers/meshes/panda_gripper/hand.stl"/>
    <mesh name="gripper0_hand_vis" file="/Users/yilongsong/Documents/Brown/robotics/MimicGen/installation_new/robosuite/robosuite/models/assets/grippers/meshes/panda_gripper/hand_vis.stl"/>
    <mesh name="gripper0_finger" file="/Users/yilongsong/Documents/Brown/robotics/MimicGen/installation_new/robosuite/robosuite/models/assets/grippers/meshes/panda_gripper/finger.stl"/>
    <mesh name="gripper0_finger_vis" file="/Users/yilongsong/Documents/Brown/robotics/MimicGen/installation_new/robosuite/robosuite/models/assets/grippers/meshes/panda_gripper/finger_vis.stl"/>
    <mesh name="gripper0_finger_vis2" file="/Users/yilongsong/Documents/Brown/robotics/MimicGen/installation_new/robosuite/robosuite/models/assets/grippers/meshes/panda_gripper/finger_longer.stl"/>
  </asset>
  <worldbody>
    <geom name="floor" size="3 3 0.125" type="plane" group="1" material="floorplane"/>
    <geom name="wall_leftcorner_visual" size="1.06 1.5 0.01" pos="-1.25 2.25 1.5" quat="0.653281 0.653281 0.270598 0.270598" type="box" contype="0" conaffinity="0" group="1" material="walls_mat"/>
    <geom name="wall_rightcorner_visual" size="1.06 1.5 0.01" pos="-1.25 -2.25 1.5" quat="0.653281 0.653281 -0.270598 -0.270598" type="box" contype="0" conaffinity="0" group="1" material="walls_mat"/>
    <geom name="wall_left_visual" size="1.75 1.5 0.01" pos="1.25 3 1.5" quat="0.707107 0.707107 0 0" type="box" contype="0" conaffinity="0" group="1" material="walls_mat"/>
    <geom name="wall_right_visual" size="1.75 1.5 0.01" pos="1.25 -3 1.5" quat="0.707107 -0.707107 0 0" type="box" contype="0" conaffinity="0" group="1" material="walls_mat"/>
    <geom name="wall_rear_visual" size="1.5 1.5 0.01" pos="-2 0 1.5" quat="0.5 0.5 0.5 0.5" type="box" contype="0" conaffinity="0" group="1" material="walls_mat"/>
    <geom name="wall_front_visual" size="3 1.5 0.01" pos="3 0 1.5" quat="0.5 0.5 -0.5 -0.5" type="box" contype="0" conaffinity="0" group="1" material="walls_mat"/>
    <camera name="frontview" pos="1.6 0 1.45" quat="0.560842 0.430646 0.430646 0.560842"/>
    <camera name="birdview" pos="-0.2 0 3" quat="0.707107 0 0 0.707107"/>
    <camera name="agentview" pos="0.598613 -4.39204e-09 1.59035" quat="0.638018 0.30485 0.30485 0.638018"/>
    <camera name="sideview" pos="-0.0565177 1.27612 1.48796" quat="0.00990507 0.00687796 0.591223 0.806418"/>
    <light pos="1 1 1.5" dir="-0.19245 -0.19245 -0.96225" directional="true" castshadow="false"/>
    <body name="table" pos="-0.2 -0.35 0.775" gravcomp="0">
      <geom name="table_collision" size="0.4 0.15 0.025" type="box" rgba="0.5 0.5 0 1"/>
      <geom name="table_visual" size="0.4 0.15 0.025" type="box" contype="0" conaffinity="0" group="1" material="table_ceramic"/>
      <geom name="table_leg1_visual" size="0.025 0.3875" pos="0.3 0 -0.3875" type="cylinder" contype="0" conaffinity="0" group="1" material="table_legs_metal"/>
      <geom name="table_leg2_visual" size="0.025 0.3875" pos="-0.3 0 -0.3875" type="cylinder" contype="0" conaffinity="0" group="1" material="table_legs_metal"/>
      <geom name="table_leg3_visual" size="0.025 0.3875" pos="-0.3 0 -0.3875" type="cylinder" contype="0" conaffinity="0" group="1" material="table_legs_metal"/>
      <geom name="table_leg4_visual" size="0.025 0.3875" pos="0.3 0 -0.3875" type="cylinder" contype="0" conaffinity="0" group="1" material="table_legs_metal"/>
      <site name="table_top" pos="0 0 0.025" size="0.001" rgba="0 0 0 0"/>
    </body>
    <body name="robot0_base" pos="-0.56 0 0.912" gravcomp="0">
      <inertial pos="0 0 0" mass="0" diaginertia="0 0 0"/>
      <camera name="robot0_robotview" pos="1 0 0.4" quat="0.653098 0.271041 0.271041 0.653098"/>
      <body name="robot0_link0" pos="0 0 0" gravcomp="0">
        <inertial pos="0 0 0.05" mass="4" diaginertia="0.4 0.4 0.4"/>
        <geom name="robot0_g0_vis" type="mesh" contype="0" conaffinity="0" group="1" material="robot0_Shell010_001" mesh="robot0_link0_vis_0"/>
        <geom name="robot0_g1_vis" type="mesh" contype="0" conaffinity="0" group="1" material="robot0_Shell009_001" mesh="robot0_link0_vis_1"/>
        <geom name="robot0_g2_vis" type="mesh" contype="0" conaffinity="0" group="1" material="robot0_Shell003_001" mesh="robot0_link0_vis_2"/>
        <geom name="robot0_g3_vis" type="mesh" contype="0" conaffinity="0" group="1" material="robot0_Shell_001" mesh="robot0_link0_vis_3"/>
        <geom name="robot0_g4_vis" type="mesh" contype="0" conaffinity="0" group="1" material="robot0_Shell002_001" mesh="robot0_link0_vis_4"/>
        <geom name="robot0_g5_vis" type="mesh" contype="0" conaffinity="0" group="1" material="robot0_Shell001_001" mesh="robot0_link0_vis_5"/>
        <geom name="robot0_g6_vis" type="mesh" contype="0" conaffinity="0" group="1" material="robot0_Face636_001" mesh="robot0_link0_vis_6"/>
        <geom name="robot0_g7_vis" type="mesh" contype="0" conaffinity="0" group="1" material="robot0_Part__Feature018_001" mesh="robot0_link0_vis_7"/>
        <geom name="robot0_g8_vis" type="mesh" contype="0" conaffinity="0" group="1" material="robot0_Part__Feature019_001" mesh="robot0_link0_vis_8"/>
        <geom name="robot0_g9_vis" type="mesh" contype="0" conaffinity="0" group="1" material="robot0_Part__Feature023_001" mesh="robot0_link0_vis_9"/>
        <geom name="robot0_g10_vis" type="mesh" contype="0" conaffinity="0" group="1" material="robot0_Part__Feature022_001" mesh="robot0_link0_vis_10"/>
        <geom name="robot0_g11_vis" type="mesh" contype="0" conaffinity="0" group="1" material="robot0_Part__Feature017_001" mesh="robot0_link0_vis_11"/>
        <geom name="robot0_link0_collision" type="mesh" rgba="0 0.5 0 1" mesh="robot0_link0"/>
        <body name="robot0_link1" pos="0 0 0.333" gravcomp="0">
          <inertial pos="0 0 -0.07" mass="3" diaginertia="0.3 0.3 0.3"/>
          <joint name="robot0_joint1" pos="0 0 0" axis="0 0 1" range="-2.8973 2.8973" armature="5" damping="0.1" frictionloss="0.1"/>
          <geom name="robot0_g12_vis" type="mesh" contype="0" conaffinity="0" group="1" material="robot0_Part__Feature_001" mesh="robot0_link1_vis"/>
          <geom name="robot0_link1_collision" type="mesh" rgba="0 0.5 0 1" mesh="robot0_link1"/>
          <body name="robot0_link2" pos="0 0 0" quat="0.707107 -0.707107 0 0" gravcomp="0">
            <inertial pos="0 -0.1 0" mass="3" diaginertia="0.3 0.3 0.3"/>
            <joint name="robot0_joint2" pos="0 0 0" axis="0 0 1" range="-1.7628 1.7628" armature="2.5" damping="0.1" frictionloss="0.1"/>
            <geom name="robot0_g13_vis" type="mesh" contype="0" conaffinity="0" group="1" material="robot0_Part__Feature024" mesh="robot0_link2_vis"/>
            <geom name="robot0_link2_collision" type="mesh" rgba="0 0.5 0 1" mesh="robot0_link2"/>
            <body name="robot0_link3" pos="0 -0.316 0" quat="0.707107 0.707107 0 0" gravcomp="0">
              <inertial pos="0.04 0 -0.05" mass="2" diaginertia="0.2 0.2 0.2"/>
              <joint name="robot0_joint3" pos="0 0 0" axis="0 0 1" range="-2.8973 2.8973" armature="1.66667" damping="0.1" frictionloss="0.1"/>
              <geom name="robot0_g14_vis" type="mesh" contype="0" conaffinity="0" group="1" material="robot0_Part__Feature003_004_001_002" mesh="robot0_link3_vis_0"/>
              <geom name="robot0_g15_vis" type="mesh" contype="0" conaffinity="0" group="1" material="robot0_Part__Feature002_007_001_002" mesh="robot0_link3_vis_1"/>
              <geom name="robot0_g16_vis" type="mesh" contype="0" conaffinity="0" group="1" material="robot0_Part__Feature001_010_001_002" mesh="robot0_link3_vis_2"/>
              <geom name="robot0_g17_vis" type="mesh" contype="0" conaffinity="0" group="1" material="robot0_Part__Feature_001_001_001_002" mesh="robot0_link3_vis_3"/>
              <geom name="robot0_link3_collision" type="mesh" rgba="0 0.5 0 1" mesh="robot0_link3"/>
              <body name="robot0_link4" pos="0.0825 0 0" quat="0.707107 0.707107 0 0" gravcomp="0">
                <inertial pos="-0.04 0.05 0" mass="2" diaginertia="0.2 0.2 0.2"/>
                <joint name="robot0_joint4" pos="0 0 0" axis="0 0 1" range="-3.0718 -0.0698" armature="1.25" damping="0.1" frictionloss="0.1"/>
                <geom name="robot0_g18_vis" type="mesh" contype="0" conaffinity="0" group="1" material="robot0_Part__Feature001_001_003_001" mesh="robot0_link4_vis_0"/>
                <geom name="robot0_g19_vis" type="mesh" contype="0" conaffinity="0" group="1" material="robot0_Part__Feature003_001_003_001" mesh="robot0_link4_vis_1"/>
                <geom name="robot0_g20_vis" type="mesh" contype="0" conaffinity="0" group="1" material="robot0_Part__Feature002_001_003_001" mesh="robot0_link4_vis_2"/>
                <geom name="robot0_g21_vis" type="mesh" contype="0" conaffinity="0" group="1" material="robot0_Part__Feature_002_003_001" mesh="robot0_link4_vis_3"/>
                <geom name="robot0_link4_collision" type="mesh" rgba="0 0.5 0 1" mesh="robot0_link4"/>
                <body name="robot0_link5" pos="-0.0825 0.384 0" quat="0.707107 -0.707107 0 0" gravcomp="0">
                  <inertial pos="0 0 -0.15" mass="2" diaginertia="0.2 0.2 0.2"/>
                  <joint name="robot0_joint5" pos="0 0 0" axis="0 0 1" range="-2.8973 2.8973" armature="1" damping="0.1" frictionloss="0.1"/>
                  <geom name="robot0_g22_vis" type="mesh" contype="0" conaffinity="0" group="1" material="robot0_Shell001_001_001_003" mesh="robot0_link5_vis_0"/>
                  <geom name="robot0_g23_vis" type="mesh" contype="0" conaffinity="0" group="1" material="robot0_Shell_001_001_003" mesh="robot0_link5_vis_1"/>
                  <geom name="robot0_g24_vis" type="mesh" contype="0" conaffinity="0" group="1" material="robot0_Part__Feature_002_004_003" mesh="robot0_link5_vis_2"/>
                  <geom name="robot0_link5_collision" type="mesh" rgba="0 0.5 0 1" mesh="robot0_link5"/>
                  <body name="robot0_link6" pos="0 0 0" quat="0.707107 0.707107 0 0" gravcomp="0">
                    <inertial pos="0.06 0 0" mass="1.5" diaginertia="0.1 0.1 0.1"/>
                    <joint name="robot0_joint6" pos="0 0 0" axis="0 0 1" range="-0.0175 3.7525" armature="0.833333" damping="0.01" frictionloss="0.1"/>
                    <geom name="robot0_g25_vis" type="mesh" contype="0" conaffinity="0" group="1" material="robot0_Shell006_003_002_001" mesh="robot0_link6_vis_0"/>
                    <geom name="robot0_g26_vis" type="mesh" contype="0" conaffinity="0" group="1" material="robot0_Shell011_002_002_001" mesh="robot0_link6_vis_1"/>
                    <geom name="robot0_g27_vis" type="mesh" contype="0" conaffinity="0" group="1" material="robot0_Shell007_002_002_001" mesh="robot0_link6_vis_2"/>
                    <geom name="robot0_g28_vis" type="mesh" contype="0" conaffinity="0" group="1" material="robot0_Shell005_001_001_002_001" mesh="robot0_link6_vis_3"/>
                    <geom name="robot0_g29_vis" type="mesh" contype="0" conaffinity="0" group="1" material="robot0_Shell004_001_001_002_001" mesh="robot0_link6_vis_4"/>
                    <geom name="robot0_g30_vis" type="mesh" contype="0" conaffinity="0" group="1" material="robot0_Shell003_002_001_002_001" mesh="robot0_link6_vis_5"/>
                    <geom name="robot0_g31_vis" type="mesh" contype="0" conaffinity="0" group="1" material="robot0_Shell002_002_001_002_001" mesh="robot0_link6_vis_6"/>
                    <geom name="robot0_g32_vis" type="mesh" contype="0" conaffinity="0" group="1" material="robot0_Union001_001_001_002_001" mesh="robot0_link6_vis_7"/>
                    <geom name="robot0_g33_vis" type="mesh" contype="0" conaffinity="0" group="1" material="robot0_Union_001_001_002_001" mesh="robot0_link6_vis_8"/>
                    <geom name="robot0_g34_vis" type="mesh" contype="0" conaffinity="0" group="1" material="robot0_Face539_002_001_002_001" mesh="robot0_link6_vis_9"/>
                    <geom name="robot0_g35_vis" type="mesh" contype="0" conaffinity="0" group="1" material="robot0_Shell_003_001_002_001" mesh="robot0_link6_vis_10"/>
                    <geom name="robot0_g36_vis" type="mesh" contype="0" conaffinity="0" group="1" material="robot0_Face374_002_001_002_001" mesh="robot0_link6_vis_11"/>
                    <geom name="robot0_g37_vis" type="mesh" contype="0" conaffinity="0" group="1" material="robot0_Face065_002_001_002_001" mesh="robot0_link6_vis_12"/>
                    <geom name="robot0_g38_vis" type="mesh" contype="0" conaffinity="0" group="1" material="robot0_Face064_002_001_002_001" mesh="robot0_link6_vis_13"/>
                    <geom name="robot0_g39_vis" type="mesh" contype="0" conaffinity="0" group="1" material="robot0_Part__Feature002_006_001_002_001" mesh="robot0_link6_vis_14"/>
                    <geom name="robot0_g40_vis" type="mesh" contype="0" conaffinity="0" group="1" material="robot0_Part__Feature001_009_001_002_001" mesh="robot0_link6_vis_15"/>
                    <geom name="robot0_g41_vis" type="mesh" contype="0" conaffinity="0" group="1" material="robot0_Shell012_002_002_001" mesh="robot0_link6_vis_16"/>
                    <geom name="robot0_link6_collision" type="mesh" rgba="0 0.5 0 1" mesh="robot0_link6"/>
                    <body name="robot0_link7" pos="0.088 0 0" quat="0.707107 0.707107 0 0" gravcomp="0">
                      <inertial pos="0 0 0.08" mass="0.5" diaginertia="0.05 0.05 0.05"/>
                      <joint name="robot0_joint7" pos="0 0 0" axis="0 0 1" range="-2.8973 2.8973" armature="0.714286" damping="0.01" frictionloss="0.1"/>
                      <geom name="robot0_g42_vis" type="mesh" contype="0" conaffinity="0" group="1" material="robot0_Part__Mirroring004_004_002" mesh="robot0_link7_vis_0"/>
                      <geom name="robot0_g43_vis" type="mesh" contype="0" conaffinity="0" group="1" material="robot0_Part__Mirroring001_004_002" mesh="robot0_link7_vis_1"/>
                      <geom name="robot0_g44_vis" type="mesh" contype="0" conaffinity="0" group="1" material="robot0_Part__Mirroring007_004_001" mesh="robot0_link7_vis_2"/>
                      <geom name="robot0_g45_vis" type="mesh" contype="0" conaffinity="0" group="1" material="robot0_Part__Mirroring006_004_001" mesh="robot0_link7_vis_3"/>
                      <geom name="robot0_g46_vis" type="mesh" contype="0" conaffinity="0" group="1" material="robot0_Part__Mirroring005_004_001" mesh="robot0_link7_vis_4"/>
                      <geom name="robot0_g47_vis" type="mesh" contype="0" conaffinity="0" group="1" material="robot0_Part__Mirroring003_004_001" mesh="robot0_link7_vis_5"/>
                      <geom name="robot0_g48_vis" type="mesh" contype="0" conaffinity="0" group="1" material="robot0_Part__Mirroring002_004_001" mesh="robot0_link7_vis_6"/>
                      <geom name="robot0_g49_vis" type="mesh" contype="0" conaffinity="0" group="1" material="robot0_Part__Mirroring_004_001" mesh="robot0_link7_vis_7"/>
                      <geom name="robot0_link7_collision" type="mesh" rgba="0 0.5 0 1" mesh="robot0_link7"/>
                      <body name="robot0_right_hand" pos="0 0 0.1065" quat="0.923785 0 0 -0.382911" gravcomp="0">
                        <inertial pos="0 0 0" mass="0.5" diaginertia="0.05 0.05 0.05"/>
                        <camera name="robot0_eye_in_hand" pos="0.05 0 0" quat="0 0.707107 0.707107 0" fovy="75"/>
                        <body name="gripper0_right_gripper" pos="0 0 0" quat="0.707107 0 0 -0.707107" gravcomp="0">
                          <inertial pos="0 0 0.17" quat="0.707107 0.707107 0 0" mass="0.3" diaginertia="0.09 0.07 0.05"/>
                          <geom name="gripper0_hand_visual" quat="0.707107 0 0 0.707107" type="mesh" contype="0" conaffinity="0" group="1" rgba="1 1 1 1" mesh="gripper0_hand_vis"/>
                          <geom name="gripper0_hand_collision" quat="0.707107 0 0 0.707107" type="mesh" rgba="0 0 0.5 1" mesh="gripper0_hand"/>
                          <site name="gripper0_ft_frame" pos="0 0 0" size="0.01" group="1" rgba="1 0 0 1"/>
                          <body name="gripper0_eef" pos="0 0 0.097" gravcomp="0">
                            <site name="gripper0_grip_site" pos="0 0 0" size="0.01" group="1" rgba="1 4.8591e-09 0 0.5"/>
                            <site name="gripper0_ee_x" pos="0.1 0 0" quat="0.707105 0 0.707108 0" size="0.005 0.1" group="1" type="cylinder" rgba="1 0 0 0"/>
                            <site name="gripper0_ee_y" pos="0 0.1 0" quat="0.707105 0.707108 0 0" size="0.005 0.1" group="1" type="cylinder" rgba="0 1 0 0"/>
                            <site name="gripper0_ee_z" pos="0 0 0.1" size="0.005 0.1" group="1" type="cylinder" rgba="0 0 1 0"/>
                            <site name="gripper0_grip_site_cylinder" pos="0 0 0" size="0.005 10" group="1" type="cylinder" rgba="0 1 0 0.3"/>
                          </body>
                          <body name="gripper0_leftfinger" pos="0 0 0.0524" quat="0.707107 0 0 0.707107" gravcomp="0">
                            <inertial pos="0 0 0.05" mass="0.1" diaginertia="0.01 0.01 0.005"/>
                            <joint name="gripper0_finger_joint1" pos="0 0 0" axis="0 1 0" type="slide" range="0 0.04" armature="1" damping="100" frictionloss="1"/>
                            <geom name="gripper0_finger1_visual" type="mesh" contype="0" conaffinity="0" group="1" rgba="0.499 0.499 0.499 1" mesh="gripper0_finger_vis"/>
                            <geom name="gripper0_finger1_collision" type="mesh" contype="0" condim="4" rgba="0 0 0.5 1" mesh="gripper0_finger"/>
                            <body name="gripper0_finger_joint1_tip" pos="0 0.0085 0.056" gravcomp="0">
                              <inertial pos="0 0 0" quat="0 0 0 1" mass="0.01" diaginertia="0.01 0.01 0.01"/>
                              <geom name="gripper0_finger1_pad_collision" size="0.008 0.004 0.008" pos="0 -0.005 -0.015" quat="0 0 0 1" type="box" friction="2 0.05 0.0001" solref="0.01 0.5" rgba="0 0 0.5 1"/>
                            </body>
                          </body>
                          <body name="gripper0_rightfinger" pos="0 0 0.0524" quat="0.707107 0 0 0.707107" gravcomp="0">
                            <inertial pos="0 0 0.05" mass="0.1" diaginertia="0.01 0.01 0.005"/>
                            <joint name="gripper0_finger_joint2" pos="0 0 0" axis="0 1 0" type="slide" range="-0.04 0" armature="1" damping="100" frictionloss="1"/>
                            <geom name="gripper0_finger2_visual" quat="0 0 0 1" type="mesh" contype="0" conaffinity="0" group="1" rgba="0.499 0.499 0.499 1" mesh="gripper0_finger_vis"/>
                            <geom name="gripper0_finger2_collision" quat="0 0 0 1" type="mesh" contype="0" condim="4" rgba="0 0 0.5 1" mesh="gripper0_finger"/>
                            <body name="gripper0_finger_joint2_tip" pos="0 -0.0085 0.056" gravcomp="0">
                              <inertial pos="0 0 0" quat="0 0 0 1" mass="0.01" diaginertia="0.01 0.01 0.01"/>
                              <geom name="gripper0_finger2_pad_collision" size="0.008 0.004 0.008" pos="0 0.005 -0.015" quat="0 0 0 1" type="box" friction="2 0.05 0.0001" solref="0.01 0.5" rgba="0 0 0.5 1"/>
                            </body>
                          </body>
                        </body>
                      </body>
                    </body>
                  </body>
                </body>
              </body>
            </body>
          </body>
        </body>
      </body>
      <body name="mount0_base" pos="0 0 0.01" gravcomp="0">
        <body name="mount0_controller_box" pos="0 0 0" gravcomp="0">
          <inertial pos="-0.325 0 -0.38" mass="46.64" diaginertia="1.71363 1.27988 0.809981"/>
          <geom name="mount0_controller_box_col" size="0.11 0.2 0.265" pos="-0.325 0 -0.38" type="box" rgba="0.5 0.5 0 1"/>
        </body>
        <body name="mount0_pedestal_feet" pos="0 0 0" gravcomp="0">
          <inertial pos="-0.1225 0 -0.758" mass="167.09" diaginertia="8.16095 9.59375 15.0785"/>
          <geom name="mount0_pedestal_feet_col" size="0.385 0.35 0.155" pos="-0.1225 0 -0.758" type="box" rgba="0.5 0.5 0 1"/>
        </body>
        <body name="mount0_torso" pos="0 0 0" gravcomp="0">
          <inertial pos="0 0 0" mass="0.0001" diaginertia="1e-08 1e-08 1e-08"/>
          <geom name="mount0_torso_vis" size="0.05 0.05 0.05" pos="0 0 -0.05" type="box" contype="0" conaffinity="0" group="1" rgba="0.2 0.2 0.2 1"/>
        </body>
        <body name="mount0_pedestal" pos="0 0 0" gravcomp="0">
          <inertial pos="0 0 0" quat="0.659267 -0.259505 -0.260945 0.655692" mass="60.864" diaginertia="6.0869 5.81635 4.20915"/>
          <geom name="mount0_pedestal_vis" type="mesh" contype="0" conaffinity="0" group="1" rgba="0.2 0.2 0.2 1" mesh="mount0_pedestal"/>
          <geom name="mount0_pedestal_col" size="0.18 0.31" pos="-0.02 0 -0.29" type="cylinder" rgba="0.5 0.5 0 1"/>
        </body>
      </body>
    </body>
    <body name="Door_main" pos="-0.12111 -0.354097 1.1" quat="0.67654 0 0 -0.736406" gravcomp="0">
      <site name="Door_default_site" pos="0 0 0" size="0.002" rgba="1 0 0 0"/>
      <body name="Door_frame" pos="0 0.22 0" quat="0.707388 0 0 -0.706825" gravcomp="0">
        <inertial pos="0.3 0 0" quat="0.5 0.5 0.5 0.5" mass="7.85398" diaginertia="0.923301 0.764585 0.168533"/>
        <geom name="Door_r_frame" size="0.03 0.3" pos="0.555 0 0" type="cylinder" rgba="0.5 0 0 1"/>
        <geom name="Door_l_frame" size="0.03 0.3" pos="0.045 0 0" type="cylinder" rgba="0.5 0 0 1"/>
        <geom name="Door_r_frame_visual" size="0.03 0.3" pos="0.555 0 0" type="cylinder" contype="0" conaffinity="0" group="1" mass="0" rgba="1 1 1 1"/>
        <geom name="Door_l_frame_visual" size="0.03 0.3" pos="0.045 0 0" type="cylinder" contype="0" conaffinity="0" group="1" mass="0" rgba="1 1 1 1"/>
        <body name="Door_door" pos="0.3 0 0" gravcomp="0">
          <inertial pos="0.0296816 -0.00152345 0" quat="0.701072 0 0 0.713091" mass="2.43455" diaginertia="0.0913751 0.0521615 0.043714"/>
          <joint name="Door_hinge" pos="0.255 0 0" axis="0 0 1" range="0 0.4" damping="1" frictionloss="1"/>
          <geom name="Door_panel" size="0.22 0.02 0.29" type="box" friction="1 1 1" rgba="0.5 0 0 1"/>
          <geom name="Door_panel_visual" size="0.22 0.02 0.29" type="box" contype="0" conaffinity="0" group="1" friction="1 1 1" mass="0" material="Door_MatDarkWood"/>
          <body name="Door_latch" pos="-0.175 0 -0.025" gravcomp="0">
            <inertial pos="-0.017762 0.0138544 0" quat="0.365653 0.605347 -0.36522 0.605365" mass="0.1" diaginertia="0.0483771 0.0410001 0.0111013"/>
            <joint name="Door_latch_joint" pos="0 0 0" axis="0 1 0" stiffness="1" range="-1.57 1.57" frictionloss="0.1"/>
            <geom name="Door_handle_base" size="0.025 0.09375" pos="0 -0.03125 0" quat="0.707107 -0.707107 0 0" type="cylinder" rgba="0.5 0 0 1"/>
            <geom name="Door_handle" size="0.075 0.015 0.02" pos="0.075 -0.1 0" type="box" rgba="0.5 0 0 1"/>
            <geom name="Door_latch" size="0.025 0.0125 0.03125" pos="-0.03125 0.05 0" quat="0.707388 0 0.706825 0" type="box" rgba="0.5 0 0 1"/>
            <geom name="Door_latch_tip" size="0.025 0.0125" pos="-0.0625 0.05 0" quat="0.707388 0.706825 0 0" type="cylinder" rgba="0.5 0 0 1"/>
            <geom name="Door_handle_base_visual" size="0.025 0.09375" pos="0 -0.03125 0" quat="0.707107 -0.707107 0 0" type="cylinder" contype="0" conaffinity="0" group="1" mass="0" material="Door_MatMetal"/>
            <geom name="Door_handle_visual" size="0.075 0.015 0.02" pos="0.075 -0.1 0" type="box" contype="0" conaffinity="0" group="1" mass="0" material="Door_MatMetal"/>
            <geom name="Door_latch_visual" size="0.025 0.0125 0.03125" pos="-0.03125 0.05 0" quat="0.707388 0 0.706825 0" type="box" contype="0" conaffinity="0" group="1" mass="0" material="Door_MatMetal"/>
            <geom name="Door_latch_tip_visual" size="0.025 0.0125" pos="-0.0625 0.05 0" quat="0.707388 0.706825 0 0" type="cylinder" contype="0" conaffinity="0" group="1" mass="0" material="Door_MatMetal"/>
            <site name="Door_handle" pos="0.125 -0.1 0" size="0.02" rgba="0 0 1 0"/>
          </body>
        </body>
      </body>
    </body>
  </worldbody>
  <actuator>
    <general name="robot0_torq_j1" joint="robot0_joint1" ctrlrange="-80 80" actdim="0"/>
    <general name="robot0_torq_j2" joint="robot0_joint2" ctrlrange="-80 80" actdim="0"/>
    <general name="robot0_torq_j3" joint="robot0_joint3" ctrlrange="-80 80" actdim="0"/>
    <general name="robot0_torq_j4" joint="robot0_joint4" ctrlrange="-80 80" actdim="0"/>
    <general name="robot0_torq_j5" joint="robot0_joint5" ctrlrange="-80 80" actdim="0"/>
    <general name="robot0_torq_j6" joint="robot0_joint6" ctrlrange="-12 12" actdim="0"/>
    <general name="robot0_torq_j7" joint="robot0_joint7" ctrlrange="-12 12" actdim="0"/>
    <general name="gripper0_gripper_finger_joint1" joint="gripper0_finger_joint1" ctrlrange="0 0.04" forcerange="-20 20" actdim="0" biastype="affine" gainprm="1000 0 0 0 0 0 0 0 0 0" biasprm="0 -1000 0 0 0 0 0 0 0 0"/>
    <general name="gripper0_gripper_finger_joint2" joint="gripper0_finger_joint2" ctrlrange="-0.04 0" forcerange="-20 20" actdim="0" biastype="affine" gainprm="1000 0 0 0 0 0 0 0 0 0" biasprm="0 -1000 0 0 0 0 0 0 0 0"/>
  </actuator>
  <sensor>
    <force site="gripper0_ft_frame" name="gripper0_force_ee"/>
    <torque site="gripper0_ft_frame" name="gripper0_torque_ee"/>
  </sensor>
</mujoco>
